Workbook

Sheet Table-View (2)
A1: 1. View Name - | I1: Please read review comments on Table Functional Description, Data Type and Business Definition
A2: 2. Table Name - | B2: AVY_FACT_SIDE
A3: 3. View Schema Name -
A4: 4. Table Schema Name - | B4: TRANSACTIONS_OWNER
A5: 5. Table Functional Description - | B5: This table consists of trades and transactions (Cash and Securities) to meet investment objective of a client. | I5: BA Responsbility | J5: BA Responsbility | K5: BA Responsbility | L5: DA Responsibility
A6: 6. Filter Criteria - | B6: Transaction Trade Date >= DATE '2017-10-01'. Refer to [ETL Notes] tab for more filters
A7: 7. Grain (Logical primary key) - | B7: Refer to [ETL Notes] tab
A8: 8. Semantic View Schema Name -
A9: 9. Semantic View Name -
A10: Note:
A11: Lighthouse Target | Y11: Source | AD11: Transformation
A12: Logical Name of Attribute (Name of column in View without underscores) | B12: Physical Name of Attribute (Name of column in Table) Supplied by DA Team | C12: Semantic Column Name | D12: Data type in Oracle VARCHAR2(n), DATE, NUMBER(m,n), TIMETSTAMP(6) | E12: Nullable in Table and in Oracle View NULL, NOT NULL | F12: Data type in Redshift | G12: Nullable in RedshiftTable | H12: Business Definition (To go into comments and into Meta Data Hub) | I12: Sample data values | J12: Action on Attribute Add,Update,Remove, Blank | K12: Action Version | L12: Table PBI Number | M12: List Functional PBI | N12: Include in View. Populated with N only when not to be shown in the view. | O12: Is on Data Model DA responsibility | P12: Model Data Type match TRUE/FALSE DA Responsibilty | Q12: Column2 | R12: Model Defs. Match | S12: Model Nullable Match | T12: On Table | U12: table data type | V12: table Nullable | W12: table defintions | X12: On View | Y12: Source Schema | Z12: Source Table | AA12: Source Attribute Name | AB12: Data Type | AC12: Nullable? | AD12: Transformation /Business Rules /Join Conditions | AE12: Notes / Comments | AF12: Indicator | AG12: Domain | AH12: Cross-Domain
A13: SHADOW Transaction Type Code | B13: SHDW_TXN_TP_CD | C13: Shadow_Transaction_Type_Code | D13: VARCHAR2(50) | E13: Yes | F13: character varying(50) | G13: Yes | H13: Possible values: ORG, OLD, NEW, REV, REP. | I13: OLD ORG REP REV NEW | J13: Add | K13: 3 | O13: =VLOOKUP(A13,[1]Model!C$2:J$559,2,FALSE)=B13 -> TRUE | P13: =VLOOKUP(A13,Model!C$2:G$228,5,FALSE)=D13 -> #N/A | Q13: =VLOOKUP(A13,[2]Model!C$2:L$228,8,FALSE) -> 179 | R13: =VLOOKUP(A13,[2]Model!C$2:G$228,3,FALSE)=[3]!Table14[[#This Row],[Business Definition (To go into comments and into Meta Data Hub)]] -> #REF! | S13: =IF([3]!Table14[[#This Row],[Nullable in Table and in Oracle View NULL, NOT NULL]]="No","NOT NULL","NULL")=VLOOKUP(A13,[2]Model!C$2:I$228,6,FALSE) -> #REF! | T13: =VLOOKUP(B13,[2]Table!A$2:F$415,1,FALSE)=[3]!Table14[[#This Row],[Physical Name of Attribute (Name of column in Table) Supplied by DA Team]] -> #REF! | U13: =VLOOKUP(B13,Table!A$2:F$319,2,FALSE)=Table14[[#This Row],[Data type in Oracle VARCHAR2(n), DATE, NUMBER(m,n), TIMETSTAMP(6)]] -> FALSE | V13: =VLOOKUP(B13,Table!A$2:F$231,3,FALSE)=Table14[[#This Row],[Nullable in Table and in Oracle View NULL, NOT NULL]] -> TRUE | W13: =VLOOKUP(B13,Table!A$2:H$228,6,FALSE)=Table14[[#This Row],[Business Definition (To go into comments and into Meta Data Hub)]] -> TRUE | X13: =VLOOKUP((UPPER(SUBSTITUTE(A13," ","_"))),'[2]Consumer View'!A$2:I$329,1,FALSE) -> SHADOW_TRANSACTION_TYPE_CODE | Y13: CCAL_REPL_OWNER | Z13: TXN | AA13: SRC_TXN_TP | AH13: N
A14: SHADOW Transaction Type Name | B14: SHDW_TXN_TP_NM | C14: Shadow_Transaction_Type | D14: VARCHAR2(50) | E14: Yes | F14: character varying(50) | G14: Yes | H14: Name of the Shadow Transaction Type Code. | J14: Add | K14: 3 | O14: =VLOOKUP(A14,[1]Model!C$2:J$559,2,FALSE)=B14 -> TRUE | P14: =VLOOKUP(A14,Model!C$2:G$228,5,FALSE)=D14 -> #N/A | Q14: =VLOOKUP(A14,[2]Model!C$2:L$228,8,FALSE) -> 177 | R14: =VLOOKUP(A14,[2]Model!C$2:G$228,3,FALSE)=[3]!Table14[[#This Row],[Business Definition (To go into comments and into Meta Data Hub)]] -> #REF! | S14: =IF([3]!Table14[[#This Row],[Nullable in Table and in Oracle View NULL, NOT NULL]]="No","NOT NULL","NULL")=VLOOKUP(A14,[2]Model!C$2:I$228,6,FALSE) -> #REF! | T14: =VLOOKUP(B14,[2]Table!A$2:F$415,1,FALSE)=[3]!Table14[[#This Row],[Physical Name of Attribute (Name of column in Table) Supplied by DA Team]] -> #REF! | U14: =VLOOKUP(B14,Table!A$2:F$319,2,FALSE)=Table14[[#This Row],[Data type in Oracle VARCHAR2(n), DATE, NUMBER(m,n), TIMETSTAMP(6)]] -> FALSE | V14: =VLOOKUP(B14,Table!A$2:F$231,3,FALSE)=Table14[[#This Row],[Nullable in Table and in Oracle View NULL, NOT NULL]] -> TRUE | W14: =VLOOKUP(B14,Table!A$2:H$228,6,FALSE)=Table14[[#This Row],[Business Definition (To go into comments and into Meta Data Hub)]] -> TRUE | X14: =VLOOKUP((UPPER(SUBSTITUTE(A14," ","_"))),'[2]Consumer View'!A$2:I$329,1,FALSE) -> SHADOW_TRANSACTION_TYPE_NAME | Y14: CCAL_REPL_OWNER | Z14: SHDW_TXN_TP | AA14: SRC_TXN_TP_NM | AD14: Look up using TXN.SRC_TXN_TP=SHDW_TXN_TP.SRC_TXN_TP | AH14: N
A15: IMPACT Source Action Code | B15: IMP_SRC_ACTN_CD | C15: IMPACT_Source_Action_Code | D15: VARCHAR2(1) | E15: Yes | F15: character varying(1) | G15: Yes | H15: Code representing Action Type in IMPACT source system | I15: M C I F A P N R Y S K Q U V T | J15: Add | K15: 3 | O15: =VLOOKUP(A15,[1]Model!C$2:J$559,2,FALSE)=B15 -> TRUE | P15: =VLOOKUP(A15,Model!C$2:G$228,5,FALSE)=D15 -> TRUE | Q15: =VLOOKUP(A15,[2]Model!C$2:L$228,8,FALSE) -> 181 | R15: =VLOOKUP(A15,[2]Model!C$2:G$228,3,FALSE)=[3]!Table14[[#This Row],[Business Definition (To go into comments and into Meta Data Hub)]] -> #REF! | S15: =IF([3]!Table14[[#This Row],[Nullable in Table and in Oracle View NULL, NOT NULL]]="No","NOT NULL","NULL")=VLOOKUP(A15,[2]Model!C$2:I$228,6,FALSE) -> #REF! | T15: =VLOOKUP(B15,[2]Table!A$2:F$415,1,FALSE)=[3]!Table14[[#This Row],[Physical Name of Attribute (Name of column in Table) Supplied by DA Team]] -> #REF! | U15: =VLOOKUP(B15,Table!A$2:F$319,2,FALSE)=Table14[[#This Row],[Data type in Oracle VARCHAR2(n), DATE, NUMBER(m,n), TIMETSTAMP(6)]] -> FALSE | V15: =VLOOKUP(B15,Table!A$2:F$231,3,FALSE)=Table14[[#This Row],[Nullable in Table and in Oracle View NULL, NOT NULL]] -> TRUE | W15: =VLOOKUP(B15,Table!A$2:H$228,6,FALSE)=Table14[[#This Row],[Business Definition (To go into comments and into Meta Data Hub)]] -> TRUE | X15: =VLOOKUP((UPPER(SUBSTITUTE(A15," ","_"))),'[2]Consumer View'!A$2:I$329,1,FALSE) -> IMPACT_SOURCE_ACTION_CODE | Y15: CCAL_REPL_OWNER | Z15: TXN | AA15: SRC_ACTN_CODE | AH15: N
A16: IMPACT Source Action Name | B16: IMP_SRC_ACTN_NM | C16: IMPACT_Source_Action | D16: VARCHAR2(100) | E16: Yes | F16: character varying(100) | G16: Yes | H16: Name representing Action Type in IMPACT source system | I16: 1 Security offering document is changed A Amend B Blind Broker Fail C Cancel D Trade Settled F Pool Factor Change I Insert K Failed Trade L Trade Canceled (was matched) M Trade Matched (was unmatched) N Trade Settled O Failed obligation in Net P Trade Settled Q Trade Revision R Rate Revision S Trade Settled T Failed Trade U Trade Un-Netted V DK W Trade Revision X Trade Unmatched (was matched) Y Trade Settled | J16: Add | K16: 3 | O16: =VLOOKUP(A16,[1]Model!C$2:J$559,2,FALSE)=B16 -> TRUE | P16: =VLOOKUP(A16,Model!C$2:G$228,5,FALSE)=D16 -> TRUE | Q16: =VLOOKUP(A16,[2]Model!C$2:L$228,8,FALSE) -> 183 | R16: =VLOOKUP(A16,[2]Model!C$2:G$228,3,FALSE)=[3]!Table14[[#This Row],[Business Definition (To go into comments and into Meta Data Hub)]] -> #REF! | S16: =IF([3]!Table14[[#This Row],[Nullable in Table and in Oracle View NULL, NOT NULL]]="No","NOT NULL","NULL")=VLOOKUP(A16,[2]Model!C$2:I$228,6,FALSE) -> #REF! | T16: =VLOOKUP(B16,[2]Table!A$2:F$415,1,FALSE)=[3]!Table14[[#This Row],[Physical Name of Attribute (Name of column in Table) Supplied by DA Team]] -> #REF! | U16: =VLOOKUP(B16,Table!A$2:F$319,2,FALSE)=Table14[[#This Row],[Data type in Oracle VARCHAR2(n), DATE, NUMBER(m,n), TIMETSTAMP(6)]] -> FALSE | V16: =VLOOKUP(B16,Table!A$2:F$231,3,FALSE)=Table14[[#This Row],[Nullable in Table and in Oracle View NULL, NOT NULL]] -> TRUE | W16: =VLOOKUP(B16,Table!A$2:H$228,6,FALSE)=Table14[[#This Row],[Business Definition (To go into comments and into Meta Data Hub)]] -> TRUE | X16: =VLOOKUP((UPPER(SUBSTITUTE(A16," ","_"))),'[2]Consumer View'!A$2:I$329,1,FALSE) -> IMPACT_SOURCE_ACTION_NAME | Y16: REFERENCE_REPL_OWNER | Z16: IMPCT_ACTION_LKU | AA16: desc_text | AD16: ccal_repl_owner.txn t left join ccal_repl_owner.impct_action_lku lk ON t.src_actn_code = impct_action_lku.action_code | AE16: Note to Dev team: IMPCT_ACTION_LKU table exists only in CDS DB but not available in SSDS/Lighthouse DB. [6/3/24]: Modified target data type for Oracle and Redshift. PBI 1912566 | AH16: N
A17: SIS Detailed Events Id | B17: SIS_DLTD_EV_ID | D17: NUMBER(38,0) | E17: Yes | F17: numeric (38,0) | G17: Yes | H17: Identifier that determines what type of transaction the record contains. For SIS activity the values depend on the record type. | I17: 3214 | J17: Add | K17: 3 | O17: =VLOOKUP(A17,[1]Model!C$2:J$559,2,FALSE)=B17 -> TRUE | P17: =VLOOKUP(A17,Model!C$2:G$228,5,FALSE)=D17 -> #N/A | Q17: =VLOOKUP(A17,[2]Model!C$2:L$228,8,FALSE) -> 144 | R17: =VLOOKUP(A17,[2]Model!C$2:G$228,3,FALSE)=[3]!Table14[[#This Row],[Business Definition (To go into comments and into Meta Data Hub)]] -> #REF! | S17: =IF([3]!Table14[[#This Row],[Nullable in Table and in Oracle View NULL, NOT NULL]]="No","NOT NULL","NULL")=VLOOKUP(A17,[2]Model!C$2:I$228,6,FALSE) -> #REF! | T17: =VLOOKUP(B17,[2]Table!A$2:F$415,1,FALSE)=[3]!Table14[[#This Row],[Physical Name of Attribute (Name of column in Table) Supplied by DA Team]] -> #REF! | U17: =VLOOKUP(B17,Table!A$2:F$319,2,FALSE)=Table14[[#This Row],[Data type in Oracle VARCHAR2(n), DATE, NUMBER(m,n), TIMETSTAMP(6)]] -> TRUE | V17: =VLOOKUP(B17,Table!A$2:F$231,3,FALSE)=Table14[[#This Row],[Nullable in Table and in Oracle View NULL, NOT NULL]] -> TRUE | W17: =VLOOKUP(B17,Table!A$2:H$228,6,FALSE)=Table14[[#This Row],[Business Definition (To go into comments and into Meta Data Hub)]] -> TRUE | X17: =VLOOKUP((UPPER(SUBSTITUTE(A17," ","_"))),'[2]Consumer View'!A$2:I$329,1,FALSE) -> SIS_DETAILED_EVENTS_ID | Y17: CCAL_REPL_OWNER | Z17: TXN | AA17: SRC_BUY_SELL_MULTI_ID | AE17: [6/3/24]: Modified target data type for Oracle and Redshift. PBI 1912566 | AH17: N
A18: SIS Detailed Events Name | B18: SIS_DLTD_EV_NM | C18: SIS_Detailed_Event_Name | D18: VARCHAR2(200) | E18: Yes | F18: character varying(200) | G18: Yes | H18: Name that determines what type of transaction the record contains. For SIS activity the values depend on the record type. | I18: 3219 Stock dividends 3214 Cash Dividend 3247 Corporate actions 3229 Cash receipts 3230 Disbursements 3234 Credit interest or Foreign Withholding 3246 Disbursements (receive stock) 3233 Debit interest 3231 Journals, Income, Expenses 3245 Cash receipts (deliver stock) | J18: Add | K18: 3 | O18: =VLOOKUP(A18,[1]Model!C$2:J$559,2,FALSE)=B18 -> TRUE | P18: =VLOOKUP(A18,Model!C$2:G$228,5,FALSE)=D18 -> #N/A | Q18: =VLOOKUP(A18,[2]Model!C$2:L$228,8,FALSE) -> 145 | R18: =VLOOKUP(A18,[2]Model!C$2:G$228,3,FALSE)=[3]!Table14[[#This Row],[Business Definition (To go into comments and into Meta Data Hub)]] -> #REF! | S18: =IF([3]!Table14[[#This Row],[Nullable in Table and in Oracle View NULL, NOT NULL]]="No","NOT NULL","NULL")=VLOOKUP(A18,[2]Model!C$2:I$228,6,FALSE) -> #REF! | T18: =VLOOKUP(B18,[2]Table!A$2:F$415,1,FALSE)=[3]!Table14[[#This Row],[Physical Name of Attribute (Name of column in Table) Supplied by DA Team]] -> #REF! | U18: =VLOOKUP(B18,Table!A$2:F$319,2,FALSE)=Table14[[#This Row],[Data type in Oracle VARCHAR2(n), DATE, NUMBER(m,n), TIMETSTAMP(6)]] -> FALSE | V18: =VLOOKUP(B18,Table!A$2:F$231,3,FALSE)=Table14[[#This Row],[Nullable in Table and in Oracle View NULL, NOT NULL]] -> TRUE | W18: =VLOOKUP(B18,Table!A$2:H$228,6,FALSE)=Table14[[#This Row],[Business Definition (To go into comments and into Meta Data Hub)]] -> TRUE | X18: =VLOOKUP((UPPER(SUBSTITUTE(A18," ","_"))),'[2]Consumer View'!A$2:I$329,1,FALSE) -> SIS_DETAILED_EVENTS_NAME | Y18: CCAL_REPL_OWNER | Z18: CL_VAL | AA18: CL_VAL_NM | AD18: ccal_repl_owner.cl_val cv left join ccal_repl_owner.cl_val cv ON cv.cl_val_id = t.SRC_BUY_SELL_MULTI_ID and cv.CL_SCM_ID = '99' | AE18: [6/3/24]: Modified target data type for Oracle and Redshift. PBI 1912566 | AH18: N (add Code, existing PBI)
A19: SIS User Id | B19: SIS_USR_ID | C19: SIS_User_Id | D19: VARCHAR2(255) | E19: Yes | F19: character varying(255) | G19: Yes | H19: Identifier of the process or user that creates the records sourced from SIS Money Movement | I19: LL015 | J19: Add | K19: 3 | O19: =VLOOKUP(A19,[1]Model!C$2:J$559,2,FALSE)=B19 -> TRUE | P19: =VLOOKUP(A19,Model!C$2:G$228,5,FALSE)=D19 -> #N/A | Q19: =VLOOKUP(A19,[2]Model!C$2:L$228,8,FALSE) -> 146 | R19: =VLOOKUP(A19,[2]Model!C$2:G$228,3,FALSE)=[3]!Table14[[#This Row],[Business Definition (To go into comments and into Meta Data Hub)]] -> #REF! | S19: =IF([3]!Table14[[#This Row],[Nullable in Table and in Oracle View NULL, NOT NULL]]="No","NOT NULL","NULL")=VLOOKUP(A19,[2]Model!C$2:I$228,6,FALSE) -> #REF! | T19: =VLOOKUP(B19,[2]Table!A$2:F$415,1,FALSE)=[3]!Table14[[#This Row],[Physical Name of Attribute (Name of column in Table) Supplied by DA Team]] -> #REF! | U19: =VLOOKUP(B19,Table!A$2:F$319,2,FALSE)=Table14[[#This Row],[Data type in Oracle VARCHAR2(n), DATE, NUMBER(m,n), TIMETSTAMP(6)]] -> FALSE | V19: =VLOOKUP(B19,Table!A$2:F$231,3,FALSE)=Table14[[#This Row],[Nullable in Table and in Oracle View NULL, NOT NULL]] -> TRUE | W19: =VLOOKUP(B19,Table!A$2:H$228,6,FALSE)=Table14[[#This Row],[Business Definition (To go into comments and into Meta Data Hub)]] -> TRUE | X19: =VLOOKUP((UPPER(SUBSTITUTE(A19," ","_"))),'[2]Consumer View'!A$2:I$329,1,FALSE) -> SIS_USER_ID | Y19: CCAL_REPL_OWNER | Z19: TXN | AA19: USR_ID | AH19: N
A20: SIS Account Classification Code | B20: SIS_AC_CL_CD | C20: SIS_Account_Classification_Code | D20: VARCHAR2(50) | E20: Yes | F20: character varying(50) | G20: Yes | H20: SIS account classification codes | I20: Z | J20: Add | K20: 3 | O20: =VLOOKUP(A20,[1]Model!C$2:J$559,2,FALSE)=B20 -> TRUE | P20: =VLOOKUP(A20,Model!C$2:G$228,5,FALSE)=D20 -> #N/A | Q20: =VLOOKUP(A20,[2]Model!C$2:L$228,8,FALSE) -> 147 | R20: =VLOOKUP(A20,[2]Model!C$2:G$228,3,FALSE)=[3]!Table14[[#This Row],[Business Definition (To go into comments and into Meta Data Hub)]] -> #REF! | S20: =IF([3]!Table14[[#This Row],[Nullable in Table and in Oracle View NULL, NOT NULL]]="No","NOT NULL","NULL")=VLOOKUP(A20,[2]Model!C$2:I$228,6,FALSE) -> #REF! | T20: =VLOOKUP(B20,[2]Table!A$2:F$415,1,FALSE)=[3]!Table14[[#This Row],[Physical Name of Attribute (Name of column in Table) Supplied by DA Team]] -> #REF! | U20: =VLOOKUP(B20,Table!A$2:F$319,2,FALSE)=Table14[[#This Row],[Data type in Oracle VARCHAR2(n), DATE, NUMBER(m,n), TIMETSTAMP(6)]] -> FALSE | V20: =VLOOKUP(B20,Table!A$2:F$231,3,FALSE)=Table14[[#This Row],[Nullable in Table and in Oracle View NULL, NOT NULL]] -> TRUE | W20: =VLOOKUP(B20,Table!A$2:H$228,6,FALSE)=Table14[[#This Row],[Business Definition (To go into comments and into Meta Data Hub)]] -> TRUE | X20: =VLOOKUP((UPPER(SUBSTITUTE(A20," ","_"))),'[2]Consumer View'!A$2:I$329,1,FALSE) -> SIS_ACCOUNT_CLASSIFICATION_CODE | Y20: CCAL_REPL_OWNER | Z20: TXN | AA20: SRC_PRIM_CL | AH20: N
A21: Source Cancellation Reason Id | B21: SRC_CNCL_RSN_ID | D21: NUMBER(38,0) | E21: Yes | F21: NUMERIC(38,0) | G21: Yes | H21: Id representing Reason for cancellation in source system | I21: 3248, 3249 | J21: Add | K21: 3 | O21: =VLOOKUP(A21,[1]Model!C$2:J$559,2,FALSE)=B21 -> TRUE | P21: =VLOOKUP(A21,Model!C$2:G$228,5,FALSE)=D21 -> #N/A | Q21: =VLOOKUP(A21,[2]Model!C$2:L$228,8,FALSE) -> 148 | R21: =VLOOKUP(A21,[2]Model!C$2:G$228,3,FALSE)=[3]!Table14[[#This Row],[Business Definition (To go into comments and into Meta Data Hub)]] -> #REF! | S21: =IF([3]!Table14[[#This Row],[Nullable in Table and in Oracle View NULL, NOT NULL]]="No","NOT NULL","NULL")=VLOOKUP(A21,[2]Model!C$2:I$228,6,FALSE) -> #REF! | T21: =VLOOKUP(B21,[2]Table!A$2:F$415,1,FALSE)=[3]!Table14[[#This Row],[Physical Name of Attribute (Name of column in Table) Supplied by DA Team]] -> #REF! | U21: =VLOOKUP(B21,Table!A$2:F$319,2,FALSE)=Table14[[#This Row],[Data type in Oracle VARCHAR2(n), DATE, NUMBER(m,n), TIMETSTAMP(6)]] -> TRUE | V21: =VLOOKUP(B21,Table!A$2:F$231,3,FALSE)=Table14[[#This Row],[Nullable in Table and in Oracle View NULL, NOT NULL]] -> TRUE | W21: =VLOOKUP(B21,Table!A$2:H$228,6,FALSE)=Table14[[#This Row],[Business Definition (To go into comments and into Meta Data Hub)]] -> TRUE | X21: =VLOOKUP((UPPER(SUBSTITUTE(A21," ","_"))),'[2]Consumer View'!A$2:I$329,1,FALSE) -> SOURCE_CANCELLATION_REASON_ID | Y21: CCAL_REPL_OWNER | Z21: TXN | AA21: SRC_CNCL_RSN_ID | AH21: N
A22: Source Cancellation Reason Code | B22: SRC_CNCL_RSN_CD | C22: Source_Cancellation_Reason_Code | D22: VARCHAR2(20) | E22: Yes | F22: character varying(20) | G22: Yes | H22: Code representing Reason for cancellation in source system Valid Values - A ,N, Y, null/blank Valid values include: 'Y' - Trade is cancelled due to correction, and will not be processed as a new trade 'N' - Trade is an outright cancel. 'A' - Trade is a cancel/correction due to allocation, and will be processed as allocated trade. | I22: Y, N, A, null | J22: Add | K22: 3 | O22: =VLOOKUP(A22,[1]Model!C$2:J$559,2,FALSE)=B22 -> TRUE | P22: =VLOOKUP(A22,Model!C$2:G$228,5,FALSE)=D22 -> #N/A | Q22: =VLOOKUP(A22,[2]Model!C$2:L$228,8,FALSE) -> 149 | R22: =VLOOKUP(A22,[2]Model!C$2:G$228,3,FALSE)=[3]!Table14[[#This Row],[Business Definition (To go into comments and into Meta Data Hub)]] -> #VALUE! | S22: =IF([3]!Table14[[#This Row],[Nullable in Table and in Oracle View NULL, NOT NULL]]="No","NOT NULL","NULL")=VLOOKUP(A22,[2]Model!C$2:I$228,6,FALSE) -> #REF! | T22: =VLOOKUP(B22,[2]Table!A$2:F$415,1,FALSE)=[3]!Table14[[#This Row],[Physical Name of Attribute (Name of column in Table) Supplied by DA Team]] -> #REF! | U22: =VLOOKUP(B22,Table!A$2:F$319,2,FALSE)=Table14[[#This Row],[Data type in Oracle VARCHAR2(n), DATE, NUMBER(m,n), TIMETSTAMP(6)]] -> FALSE | V22: =VLOOKUP(B22,Table!A$2:F$231,3,FALSE)=Table14[[#This Row],[Nullable in Table and in Oracle View NULL, NOT NULL]] -> TRUE | W22: =VLOOKUP(B22,Table!A$2:H$228,6,FALSE)=Table14[[#This Row],[Business Definition (To go into comments and into Meta Data Hub)]] -> FALSE | X22: =VLOOKUP((UPPER(SUBSTITUTE(A22," ","_"))),'[2]Consumer View'!A$2:I$329,1,FALSE) -> SOURCE_CANCELLATION_REASON_CODE | Y22: CCAL_REPL_OWNER | Z22: CL_VAL | AA22: CL_VAL_CODE | AD22: ccal_repl_owner.txn t left join ccal_repl_owner.cl_val cv ON cl_val.cl_val_id = t.SRC_CNCL_RSN_ID cs.cl_scm_id = '102' | AE22: [6/3/24]: Modified target data type for Oracle and Redshift. PBI 1912566 | AH22: N
A23: Source Cancellation Reason Name | B23: SRC_CNCL_RSN_NM | C23: Source_Cancellation_Reason | D23: VARCHAR2(200) | E23: Yes | F23: character varying(200) | G23: Yes | H23: Name representing Reason for cancellation in source system | I23: Correction Outright Cancel Account Allocation | J23: Add | K23: 3 | O23: =VLOOKUP(A23,[1]Model!C$2:J$559,2,FALSE)=B23 -> TRUE | P23: =VLOOKUP(A23,Model!C$2:G$228,5,FALSE)=D23 -> #N/A | Q23: =VLOOKUP(A23,[2]Model!C$2:L$228,8,FALSE) -> 150 | R23: =VLOOKUP(A23,[2]Model!C$2:G$228,3,FALSE)=[3]!Table14[[#This Row],[Business Definition (To go into comments and into Meta Data Hub)]] -> #REF! | S23: =IF([3]!Table14[[#This Row],[Nullable in Table and in Oracle View NULL, NOT NULL]]="No","NOT NULL","NULL")=VLOOKUP(A23,[2]Model!C$2:I$228,6,FALSE) -> #REF! | T23: =VLOOKUP(B23,[2]Table!A$2:F$415,1,FALSE)=[3]!Table14[[#This Row],[Physical Name of Attribute (Name of column in Table) Supplied by DA Team]] -> #REF! | U23: =VLOOKUP(B23,Table!A$2:F$319,2,FALSE)=Table14[[#This Row],[Data type in Oracle VARCHAR2(n), DATE, NUMBER(m,n), TIMETSTAMP(6)]] -> FALSE | V23: =VLOOKUP(B23,Table!A$2:F$231,3,FALSE)=Table14[[#This Row],[Nullable in Table and in Oracle View NULL, NOT NULL]] -> TRUE | W23: =VLOOKUP(B23,Table!A$2:H$228,6,FALSE)=Table14[[#This Row],[Business Definition (To go into comments and into Meta Data Hub)]] -> TRUE | X23: =VLOOKUP((UPPER(SUBSTITUTE(A23," ","_"))),'[2]Consumer View'!A$2:I$329,1,FALSE) -> SOURCE_CANCELLATION_REASON_NAME | Y23: CCAL_REPL_OWNER | Z23: CL_VAL | AA23: CL_VAL_NM | AD23: ccal_repl_owner.txn t left join ccal_repl_owner.cl_val cv ON cl_val.cl_val_id = t.SRC_CNCL_RSN_ID cs.cl_scm_id = '102' | AH23: N
A24: Source Transaction Sequence Number | B24: SRC_TXN_SEQ_NUM | C24: Source_Transaction_Sequence_Number | D24: NUMBER(38,0) | E24: Yes | F24: NUMERIC(38,0) | G24: Yes | H24: Transaction number assigned to the transaction in the source system. | I24: 2878 | J24: Add | K24: 3 | O24: =VLOOKUP(A24,[1]Model!C$2:J$559,2,FALSE)=B24 -> TRUE | P24: =VLOOKUP(A24,Model!C$2:G$228,5,FALSE)=D24 -> #N/A | Q24: =VLOOKUP(A24,[2]Model!C$2:L$228,8,FALSE) -> 151 | R24: =VLOOKUP(A24,[2]Model!C$2:G$228,3,FALSE)=[3]!Table14[[#This Row],[Business Definition (To go into comments and into Meta Data Hub)]] -> #REF! | S24: =IF([3]!Table14[[#This Row],[Nullable in Table and in Oracle View NULL, NOT NULL]]="No","NOT NULL","NULL")=VLOOKUP(A24,[2]Model!C$2:I$228,6,FALSE) -> #REF! | T24: =VLOOKUP(B24,[2]Table!A$2:F$415,1,FALSE)=[3]!Table14[[#This Row],[Physical Name of Attribute (Name of column in Table) Supplied by DA Team]] -> #REF! | U24: =VLOOKUP(B24,Table!A$2:F$319,2,FALSE)=Table14[[#This Row],[Data type in Oracle VARCHAR2(n), DATE, NUMBER(m,n), TIMETSTAMP(6)]] -> TRUE | V24: =VLOOKUP(B24,Table!A$2:F$231,3,FALSE)=Table14[[#This Row],[Nullable in Table and in Oracle View NULL, NOT NULL]] -> TRUE | W24: =VLOOKUP(B24,Table!A$2:H$228,6,FALSE)=Table14[[#This Row],[Business Definition (To go into comments and into Meta Data Hub)]] -> TRUE | X24: =VLOOKUP((UPPER(SUBSTITUTE(A24," ","_"))),'[2]Consumer View'!A$2:I$329,1,FALSE) -> SOURCE_TRANSACTION_SEQUENCE_NUMBER | Y24: CCAL_REPL_OWNER | Z24: TXN | AA24: SRC_TXN_SEQ_NUM | AH24: N
A25: Dividend Record Date | B25: DVDN_RCRD_DT | C25: Dividend_Record_Date | D25: DATE | E25: Yes | F25: timestamp without time zone | G25: Yes | H25: The cut-off date that an organization is expected to use to determine which shareholders are eligible to receive a dividend or income distribution. | I25: 42398 | J25: Add | K25: 3 | O25: =VLOOKUP(A25,[1]Model!C$2:J$559,2,FALSE)=B25 -> TRUE | P25: =VLOOKUP(A25,Model!C$2:G$228,5,FALSE)=D25 -> TRUE | Q25: =VLOOKUP(A25,[2]Model!C$2:L$228,8,FALSE) -> 152 | R25: =VLOOKUP(A25,[2]Model!C$2:G$228,3,FALSE)=[3]!Table14[[#This Row],[Business Definition (To go into comments and into Meta Data Hub)]] -> #REF! | S25: =IF([3]!Table14[[#This Row],[Nullable in Table and in Oracle View NULL, NOT NULL]]="No","NOT NULL","NULL")=VLOOKUP(A25,[2]Model!C$2:I$228,6,FALSE) -> #REF! | T25: =VLOOKUP(B25,[2]Table!A$2:F$415,1,FALSE)=[3]!Table14[[#This Row],[Physical Name of Attribute (Name of column in Table) Supplied by DA Team]] -> #REF! | U25: =VLOOKUP(B25,Table!A$2:F$319,2,FALSE)=Table14[[#This Row],[Data type in Oracle VARCHAR2(n), DATE, NUMBER(m,n), TIMETSTAMP(6)]] -> TRUE | V25: =VLOOKUP(B25,Table!A$2:F$231,3,FALSE)=Table14[[#This Row],[Nullable in Table and in Oracle View NULL, NOT NULL]] -> TRUE | W25: =VLOOKUP(B25,Table!A$2:H$228,6,FALSE)=Table14[[#This Row],[Business Definition (To go into comments and into Meta Data Hub)]] -> TRUE | X25: =VLOOKUP((UPPER(SUBSTITUTE(A25," ","_"))),'[2]Consumer View'!A$2:I$329,1,FALSE) -> DIVIDEND_RECORD_DATE | Y25: CCAL_REPL_OWNER | Z25: TXN | AA25: DVDN_RCRD_DT | AH25: N
A26: Owner IMPACT FA Number | B26: OWN_IMP_FA_NUM | C26: Brokerage_Owner_FA_Fixed_Income_IMPACT_Number | D26: VARCHAR2(20) | E26: Yes | F26: character varying(20) | G26: Yes | H26: FA Number as given in Impact system | I26: 01A | J26: Add | K26: 3 | O26: =VLOOKUP(A26,[1]Model!C$2:J$559,2,FALSE)=B26 -> TRUE | P26: =VLOOKUP(A26,Model!C$2:G$228,5,FALSE)=D26 -> TRUE | Q26: =VLOOKUP(A26,[2]Model!C$2:L$228,8,FALSE) -> 153 | R26: =VLOOKUP(A26,[2]Model!C$2:G$228,3,FALSE)=[3]!Table14[[#This Row],[Business Definition (To go into comments and into Meta Data Hub)]] -> #REF! | S26: =IF([3]!Table14[[#This Row],[Nullable in Table and in Oracle View NULL, NOT NULL]]="No","NOT NULL","NULL")=VLOOKUP(A26,[2]Model!C$2:I$228,6,FALSE) -> #REF! | T26: =VLOOKUP(B26,[2]Table!A$2:F$415,1,FALSE)=[3]!Table14[[#This Row],[Physical Name of Attribute (Name of column in Table) Supplied by DA Team]] -> #REF! | U26: =VLOOKUP(B26,Table!A$2:F$319,2,FALSE)=Table14[[#This Row],[Data type in Oracle VARCHAR2(n), DATE, NUMBER(m,n), TIMETSTAMP(6)]] -> FALSE | V26: =VLOOKUP(B26,Table!A$2:F$231,3,FALSE)=Table14[[#This Row],[Nullable in Table and in Oracle View NULL, NOT NULL]] -> TRUE | W26: =VLOOKUP(B26,Table!A$2:H$228,6,FALSE)=Table14[[#This Row],[Business Definition (To go into comments and into Meta Data Hub)]] -> TRUE | X26: =VLOOKUP((UPPER(SUBSTITUTE(A26," ","_"))),'[2]Consumer View'!A$2:I$329,1,FALSE) -> OWNER_IMPACT_FA_NUMBER | Y26: CCAL_REPL_OWNER | Z26: TXN | AA26: SALE_PSN_NUM | AH26: N
A27: Owner FA Number | B27: OWN_FA_NUM | C27: Brokerage_Owner_FA_Number | D27: VARCHAR2(6) | E27: Yes | F27: character varying(6) | G27: Yes | H27: Owner FA Number is a FA Number that owns the Arrangement for which activity is recorded | I27: 25T3 | J27: Add | K27: 3 | O27: =VLOOKUP(A27,[1]Model!C$2:J$559,2,FALSE)=B27 -> TRUE | P27: =VLOOKUP(A27,Model!C$2:G$228,5,FALSE)=D27 -> TRUE | Q27: =VLOOKUP(A27,[2]Model!C$2:L$228,8,FALSE) -> 154 | R27: =VLOOKUP(A27,[2]Model!C$2:G$228,3,FALSE)=[3]!Table14[[#This Row],[Business Definition (To go into comments and into Meta Data Hub)]] -> #REF! | S27: =IF([3]!Table14[[#This Row],[Nullable in Table and in Oracle View NULL, NOT NULL]]="No","NOT NULL","NULL")=VLOOKUP(A27,[2]Model!C$2:I$228,6,FALSE) -> #REF! | T27: =VLOOKUP(B27,[2]Table!A$2:F$415,1,FALSE)=[3]!Table14[[#This Row],[Physical Name of Attribute (Name of column in Table) Supplied by DA Team]] -> #REF! | U27: =VLOOKUP(B27,Table!A$2:F$319,2,FALSE)=Table14[[#This Row],[Data type in Oracle VARCHAR2(n), DATE, NUMBER(m,n), TIMETSTAMP(6)]] -> FALSE | V27: =VLOOKUP(B27,Table!A$2:F$231,3,FALSE)=Table14[[#This Row],[Nullable in Table and in Oracle View NULL, NOT NULL]] -> TRUE | W27: =VLOOKUP(B27,Table!A$2:H$228,6,FALSE)=Table14[[#This Row],[Business Definition (To go into comments and into Meta Data Hub)]] -> TRUE | X27: =VLOOKUP((UPPER(SUBSTITUTE(A27," ","_"))),'[2]Consumer View'!A$2:I$329,1,FALSE) -> OWNER_FA_NUMBER | Y27: CCSI_OWNER | Z27: AR_GRP_SUBDIM | AA27: FA_NUM | AD27: select fa.FA_NUM from ccal_repl_owner.txn t LEFT JOIN ccsi_owner.AR_GRP_SUBDIM fa ON t.AR_ID = fa.AR_ID and t.td >= fa.EFF_DT and t.td < fa.END_DT; | AE27: [9/11/24]: Reflected the change to use TXN.TD from Product Backlog Item 1912566: Change join condition and update data types for Activity | AH27: Y
A28: Owner FA Number Entity Code | B28: OWN_FA_NUM_ENT_CD | C28: Brokerage_Owner_FA_Number_Entity_Code | D28: VARCHAR2(20) | E28: Yes | F28: character varying(20) | G28: Yes | H28: Entity Code that owns the Owner FA Number | I28: 10D00 | J28: Add | K28: 3 | O28: =VLOOKUP(A28,[1]Model!C$2:J$559,2,FALSE)=B28 -> TRUE | P28: =VLOOKUP(A28,Model!C$2:G$228,5,FALSE)=D28 -> TRUE | Q28: =VLOOKUP(A28,[2]Model!C$2:L$228,8,FALSE) -> 155 | R28: =VLOOKUP(A28,[2]Model!C$2:G$228,3,FALSE)=[3]!Table14[[#This Row],[Business Definition (To go into comments and into Meta Data Hub)]] -> #REF! | S28: =IF([3]!Table14[[#This Row],[Nullable in Table and in Oracle View NULL, NOT NULL]]="No","NOT NULL","NULL")=VLOOKUP(A28,[2]Model!C$2:I$228,6,FALSE) -> #REF! | T28: =VLOOKUP(B28,[2]Table!A$2:F$415,1,FALSE)=[3]!Table14[[#This Row],[Physical Name of Attribute (Name of column in Table) Supplied by DA Team]] -> #REF! | U28: =VLOOKUP(B28,Table!A$2:F$319,2,FALSE)=Table14[[#This Row],[Data type in Oracle VARCHAR2(n), DATE, NUMBER(m,n), TIMETSTAMP(6)]] -> FALSE | V28: =VLOOKUP(B28,Table!A$2:F$231,3,FALSE)=Table14[[#This Row],[Nullable in Table and in Oracle View NULL, NOT NULL]] -> TRUE | W28: =VLOOKUP(B28,Table!A$2:H$228,6,FALSE)=Table14[[#This Row],[Business Definition (To go into comments and into Meta Data Hub)]] -> TRUE | X28: =VLOOKUP((UPPER(SUBSTITUTE(A28," ","_"))),'[2]Consumer View'!A$2:I$329,1,FALSE) -> OWNER_FA_NUMBER_ENTITY_CODE | Y28: SSDS_DAL_OWNER | Z28: FA_NUMBER_V | AA28: FA_NUMBER_ENTITY_CODE | AD28: Derive based on OWN_FA_NUM field. left join SSDS_DAL_OWNER.FA_NUMBER_V fn on fn.FA_NUMBER = OWN_FA_NUM and t.td >= fn.EFF_DT AND t.td < fn.END_DT | AE28: [6/8/24]: Modified target data type for Oracle and Redshift. PBI 1912566 [9/11/24]: Reflected the change to use TXN.TD from Product Backlog Item 1912566: Change join condition and update data types for Activity | AH28: Y
A29: Owner FA Employee Id | B29: FA_OWN_EMPE_ID | C29: Brokerage_Owner_FA_Responsible_Party_Employee_ID | D29: VARCHAR2(44) | E29: Yes | F29: character varying(44) | G29: Yes | H29: PeopleWorks Identifier for the Responsible Party for an FA Number | I29: 49139 | J29: Add | K29: 3 | O29: =VLOOKUP(A29,[1]Model!C$2:J$559,2,FALSE)=B29 -> TRUE | P29: =VLOOKUP(A29,Model!C$2:G$228,5,FALSE)=D29 -> TRUE | Q29: =VLOOKUP(A29,[2]Model!C$2:L$228,8,FALSE) -> 156 | R29: =VLOOKUP(A29,[2]Model!C$2:G$228,3,FALSE)=[3]!Table14[[#This Row],[Business Definition (To go into comments and into Meta Data Hub)]] -> #REF! | S29: =IF([3]!Table14[[#This Row],[Nullable in Table and in Oracle View NULL, NOT NULL]]="No","NOT NULL","NULL")=VLOOKUP(A29,[2]Model!C$2:I$228,6,FALSE) -> #REF! | T29: =VLOOKUP(B29,[2]Table!A$2:F$415,1,FALSE)=[3]!Table14[[#This Row],[Physical Name of Attribute (Name of column in Table) Supplied by DA Team]] -> #REF! | U29: =VLOOKUP(B29,Table!A$2:F$319,2,FALSE)=Table14[[#This Row],[Data type in Oracle VARCHAR2(n), DATE, NUMBER(m,n), TIMETSTAMP(6)]] -> FALSE | V29: =VLOOKUP(B29,Table!A$2:F$231,3,FALSE)=Table14[[#This Row],[Nullable in Table and in Oracle View NULL, NOT NULL]] -> TRUE | W29: =VLOOKUP(B29,Table!A$2:H$228,6,FALSE)=Table14[[#This Row],[Business Definition (To go into comments and into Meta Data Hub)]] -> TRUE | X29: =VLOOKUP((UPPER(SUBSTITUTE(A29," ","_"))),'[2]Consumer View'!A$2:I$329,1,FALSE) -> OWNER_FA_EMPLOYEE_ID | Y29: SSDS_DAL_OWNER | Z29: FA_NUMBER_V | AA29: RESPONSIBLE_PARTY_EMPLOYEE_ID | AE29: [6/8/24]: Modified target data type for Oracle and Redshift. PBI 1912566 | AH29: Y
A30: Owner FA Number Entity Enterprise Id | B30: OWN_FA_NUM_ENT_ENTP_ID | C30: Brokerage_Owner_FA_entity_enterprise_id | D30: NUMBER(22,0) | E30: Yes | F30: NUMERIC(22,0) | G30: Yes | H30: Enterprise Id of the Entity that owns the Owner FA Number | I30: AHK00 | J30: Add | K30: 3 | O30: =VLOOKUP(A30,[1]Model!C$2:J$559,2,FALSE)=B30 -> TRUE | P30: =VLOOKUP(A30,Model!C$2:G$228,5,FALSE)=D30 -> TRUE | Q30: =VLOOKUP(A30,[2]Model!C$2:L$228,8,FALSE) -> 157 | R30: =VLOOKUP(A30,[2]Model!C$2:G$228,3,FALSE)=[3]!Table14[[#This Row],[Business Definition (To go into comments and into Meta Data Hub)]] -> #REF! | S30: =IF([3]!Table14[[#This Row],[Nullable in Table and in Oracle View NULL, NOT NULL]]="No","NOT NULL","NULL")=VLOOKUP(A30,[2]Model!C$2:I$228,6,FALSE) -> #REF! | T30: =VLOOKUP(B30,[2]Table!A$2:F$415,1,FALSE)=[3]!Table14[[#This Row],[Physical Name of Attribute (Name of column in Table) Supplied by DA Team]] -> #REF! | U30: =VLOOKUP(B30,Table!A$2:F$319,2,FALSE)=Table14[[#This Row],[Data type in Oracle VARCHAR2(n), DATE, NUMBER(m,n), TIMETSTAMP(6)]] -> TRUE | V30: =VLOOKUP(B30,Table!A$2:F$231,3,FALSE)=Table14[[#This Row],[Nullable in Table and in Oracle View NULL, NOT NULL]] -> TRUE | W30: =VLOOKUP(B30,Table!A$2:H$228,6,FALSE)=Table14[[#This Row],[Business Definition (To go into comments and into Meta Data Hub)]] -> TRUE | X30: =VLOOKUP((UPPER(SUBSTITUTE(A30," ","_"))),'[2]Consumer View'!A$2:I$329,1,FALSE) -> OWNER_FA_NUMBER_ENTITY_ENTERPRISE_ID | Y30: SSDS_DAL_OWNER | Z30: ENTERPRISE_ENTITY_DIM_V | AA30: ENTITY_ENTERPRISE_ID | AD30: Derive based on OWN_FA_NUM_ENT_CD field. LEFT JOIN SSDS_DAL_OWNER.ENTERPRISE_ENTITY_DIM_V e ON e.Entity_code_long = OWN_FA_NUM_ENT_CD AND t.td >= e.EFF_DT AND t.td < e.END_DT AND e.ENTITY_RECYCLED_BOOLEAN='0' AND e.ENTITY_FINANCIAL_RIA_BOOLEAN = '0' | AE30: [6/5/24]: Updated data type from VARCHAR to NUMBER. PBI 1912566 [6/25/24]: As a part of PBI 1912566 ROWNUM logic to pick one record at the very last stage was implemented to avoid duplicates in Entity Dim. The logic is to be revised in the future to write an exception for dupes [9/11/24]: Reflected the change to use TXN.TD from Product Backlog Item 1912566: Change join condition and update data types for Activity | AH30: Y (PBI 1931139)
A31: ACAT Contra Firm Clearing Number | B31: ACAT_CNTRA_FIRM_CLRG_NUM | C31: ACAT_Contra_Firm_Clearing_Number | D31: VARCHAR2(4) | E31: Yes | F31: character varying(4) | G31: Yes | H31: This is the logical identifier for the entity/system (in this case ACAT) that is providing this transaction information or responsible for creation/maintenance of the information. In a case where the information is created and maintained. Identifier of the system from which CDS database receives/obtains the underlying record. This identifier is specifc to ACAT Contra Firm clearing | I31: 0352 | J31: Add | K31: 3 | O31: =VLOOKUP(A31,[1]Model!C$2:J$559,2,FALSE)=B31 -> TRUE | P31: =VLOOKUP(A31,Model!C$2:G$228,5,FALSE)=D31 -> TRUE | Q31: =VLOOKUP(A31,[2]Model!C$2:L$228,8,FALSE) -> 158 | R31: =VLOOKUP(A31,[2]Model!C$2:G$228,3,FALSE)=[3]!Table14[[#This Row],[Business Definition (To go into comments and into Meta Data Hub)]] -> #VALUE! | S31: =IF([3]!Table14[[#This Row],[Nullable in Table and in Oracle View NULL, NOT NULL]]="No","NOT NULL","NULL")=VLOOKUP(A31,[2]Model!C$2:I$228,6,FALSE) -> #REF! | T31: =VLOOKUP(B31,[2]Table!A$2:F$415,1,FALSE)=[3]!Table14[[#This Row],[Physical Name of Attribute (Name of column in Table) Supplied by DA Team]] -> #REF! | U31: =VLOOKUP(B31,Table!A$2:F$319,2,FALSE)=Table14[[#This Row],[Data type in Oracle VARCHAR2(n), DATE, NUMBER(m,n), TIMETSTAMP(6)]] -> FALSE | V31: =VLOOKUP(B31,Table!A$2:F$231,3,FALSE)=Table14[[#This Row],[Nullable in Table and in Oracle View NULL, NOT NULL]] -> TRUE | W31: =VLOOKUP(B31,Table!A$2:H$228,6,FALSE)=Table14[[#This Row],[Business Definition (To go into comments and into Meta Data Hub)]] -> FALSE | X31: =VLOOKUP((UPPER(SUBSTITUTE(A31," ","_"))),'[2]Consumer View'!A$2:I$329,1,FALSE) -> ACAT_CONTRA_FIRM_CLEARING_NUMBER | Y31: CCAL_REPL_OWNER | Z31: TXN | AA31: ORIG_SRC_STM_CODE | AD31: ccal_repl_owner.txn t where t.src_stm_id IN ( 53, 54 ) | AH31: N
A32: ACAT Contra Firm Name | B32: ACAT_CNTRA_FIRM_NM | C32: ACAT_Contra_Firm | D32: VARCHAR2(50) | E32: Yes | F32: character varying(50) | G32: Yes | H32: ACAT Contra Firm Clearing Name | I32: 0352 | J32: Add | K32: 3 | O32: =VLOOKUP(A32,[1]Model!C$2:J$559,2,FALSE)=B32 -> TRUE | P32: =VLOOKUP(A32,Model!C$2:G$228,5,FALSE)=D32 -> TRUE | Q32: =VLOOKUP(A32,[2]Model!C$2:L$228,8,FALSE) -> 159 | R32: =VLOOKUP(A32,[2]Model!C$2:G$228,3,FALSE)=[3]!Table14[[#This Row],[Business Definition (To go into comments and into Meta Data Hub)]] -> #REF! | S32: =IF([3]!Table14[[#This Row],[Nullable in Table and in Oracle View NULL, NOT NULL]]="No","NOT NULL","NULL")=VLOOKUP(A32,[2]Model!C$2:I$228,6,FALSE) -> #REF! | T32: =VLOOKUP(B32,[2]Table!A$2:F$415,1,FALSE)=[3]!Table14[[#This Row],[Physical Name of Attribute (Name of column in Table) Supplied by DA Team]] -> #REF! | U32: =VLOOKUP(B32,Table!A$2:F$319,2,FALSE)=Table14[[#This Row],[Data type in Oracle VARCHAR2(n), DATE, NUMBER(m,n), TIMETSTAMP(6)]] -> FALSE | V32: =VLOOKUP(B32,Table!A$2:F$231,3,FALSE)=Table14[[#This Row],[Nullable in Table and in Oracle View NULL, NOT NULL]] -> TRUE | W32: =VLOOKUP(B32,Table!A$2:H$228,6,FALSE)=Table14[[#This Row],[Business Definition (To go into comments and into Meta Data Hub)]] -> TRUE | X32: =VLOOKUP((UPPER(SUBSTITUTE(A32," ","_"))),'[2]Consumer View'!A$2:I$329,1,FALSE) -> ACAT_CONTRA_FIRM_NAME | Y32: CCAL_REPL_OWNER | Z32: ACATS_BROKER | AA32: BROKER_NAME | AD32: ccal_repl_owner.txn t LEFT join ccal_repl_owner.acats_broker ON b.broker_id = t.orig_src_stm_code and t.src_stm_id IN ( 53, 54 ) | AE32: Note to Dev team: ACATS_BROKER table is available in CDS DB but not available in SSDS/Lighthouse DB. [11/18/25] Corrected orig_src_stm_id with orig_src_stm_code in mapping | AH32: N
A33: ACAT Contra Firm Short Name | B33: ACAT_CNTRA_FIRM_SHRT_NM | D33: VARCHAR2(15) | E33: Yes | F33: character varying(15) | G33: Yes | H33: ACAT Contra Firm Clearing Short Name | I33: 0352 | J33: Add | K33: 3 | O33: =VLOOKUP(A33,[1]Model!C$2:J$559,2,FALSE)=B33 -> TRUE | P33: =VLOOKUP(A33,Model!C$2:G$228,5,FALSE)=D33 -> TRUE | Q33: =VLOOKUP(A33,[2]Model!C$2:L$228,8,FALSE) -> 160 | R33: =VLOOKUP(A33,[2]Model!C$2:G$228,3,FALSE)=[3]!Table14[[#This Row],[Business Definition (To go into comments and into Meta Data Hub)]] -> #REF! | S33: =IF([3]!Table14[[#This Row],[Nullable in Table and in Oracle View NULL, NOT NULL]]="No","NOT NULL","NULL")=VLOOKUP(A33,[2]Model!C$2:I$228,6,FALSE) -> #REF! | T33: =VLOOKUP(B33,[2]Table!A$2:F$415,1,FALSE)=[3]!Table14[[#This Row],[Physical Name of Attribute (Name of column in Table) Supplied by DA Team]] -> #REF! | U33: =VLOOKUP(B33,Table!A$2:F$319,2,FALSE)=Table14[[#This Row],[Data type in Oracle VARCHAR2(n), DATE, NUMBER(m,n), TIMETSTAMP(6)]] -> FALSE | V33: =VLOOKUP(B33,Table!A$2:F$231,3,FALSE)=Table14[[#This Row],[Nullable in Table and in Oracle View NULL, NOT NULL]] -> TRUE | W33: =VLOOKUP(B33,Table!A$2:H$228,6,FALSE)=Table14[[#This Row],[Business Definition (To go into comments and into Meta Data Hub)]] -> TRUE | X33: =VLOOKUP((UPPER(SUBSTITUTE(A33," ","_"))),'[2]Consumer View'!A$2:I$329,1,FALSE) -> ACAT_CONTRA_FIRM_SHORT_NAME | Y33: CCAL_REPL_OWNER | Z33: ACATS_BROKER | AA33: BROKER_SHORT_NAME | AD33: ccal_repl_owner.txn t LEFT join ccal_repl_owner.acats_broker ON b.broker_id = t.orig_src_stm_code and t.src_stm_id IN ( 53, 54 ) | AE33: Note to Dev team: ACATS_BROKER table is available in CDS DB but not available in SSDS/Lighthouse DB. | AH33: N
A34: ACAT Contra Firm Clearing ID Type Code | B34: ACAT_CNTRA_FIRM_CLRG_ID_TP_CD | D34: VARCHAR2(1) | E34: Yes | F34: character varying(1) | G34: Yes | H34: ACAT Broker ID Type | I34: 2 | J34: Add | K34: 3 | O34: =VLOOKUP(A34,[1]Model!C$2:J$559,2,FALSE)=B34 -> TRUE | P34: =VLOOKUP(A34,Model!C$2:G$228,5,FALSE)=D34 -> TRUE | Q34: =VLOOKUP(A34,[2]Model!C$2:L$228,8,FALSE) -> 161 | R34: =VLOOKUP(A34,[2]Model!C$2:G$228,3,FALSE)=[3]!Table14[[#This Row],[Business Definition (To go into comments and into Meta Data Hub)]] -> #REF! | S34: =IF([3]!Table14[[#This Row],[Nullable in Table and in Oracle View NULL, NOT NULL]]="No","NOT NULL","NULL")=VLOOKUP(A34,[2]Model!C$2:I$228,6,FALSE) -> #REF! | T34: =VLOOKUP(B34,[2]Table!A$2:F$415,1,FALSE)=[3]!Table14[[#This Row],[Physical Name of Attribute (Name of column in Table) Supplied by DA Team]] -> #REF! | U34: =VLOOKUP(B34,Table!A$2:F$319,2,FALSE)=Table14[[#This Row],[Data type in Oracle VARCHAR2(n), DATE, NUMBER(m,n), TIMETSTAMP(6)]] -> FALSE | V34: =VLOOKUP(B34,Table!A$2:F$231,3,FALSE)=Table14[[#This Row],[Nullable in Table and in Oracle View NULL, NOT NULL]] -> TRUE | W34: =VLOOKUP(B34,Table!A$2:H$228,6,FALSE)=Table14[[#This Row],[Business Definition (To go into comments and into Meta Data Hub)]] -> TRUE | X34: =VLOOKUP((UPPER(SUBSTITUTE(A34," ","_"))),'[2]Consumer View'!A$2:I$329,1,FALSE) -> ACAT_CONTRA_FIRM_CLEARING_ID_TYPE_CODE | Y34: CCAL_REPL_OWNER | Z34: ACATS_BROKER | AA34: BROKER_ID_TYPE | AD34: ccal_repl_owner.txn t LEFT join ccal_repl_owner.acats_broker b ON b.broker_id = t.orig_src_stm_code and t.src_stm_id IN ( 53, 54 ) | AE34: Note to Dev team: ACATS_BROKER table is available in CDS DB but not available in SSDS/Lighthouse DB. | AH34: N
A35: Money Movement Alternate Id | B35: MM_ALT_ID | C35: Money_Movement_Alternate_Id | D35: VARCHAR2(50) | E35: Yes | F35: character varying(50) | G35: Yes | H35: Identifier on all Money movement transactions | I35: MM1423054 | J35: Add | K35: 3 | O35: =VLOOKUP(A35,[1]Model!C$2:J$559,2,FALSE)=B35 -> TRUE | P35: =VLOOKUP(A35,Model!C$2:G$228,5,FALSE)=D35 -> TRUE | Q35: =VLOOKUP(A35,[2]Model!C$2:L$228,8,FALSE) -> 162 | R35: =VLOOKUP(A35,[2]Model!C$2:G$228,3,FALSE)=[3]!Table14[[#This Row],[Business Definition (To go into comments and into Meta Data Hub)]] -> #REF! | S35: =IF([3]!Table14[[#This Row],[Nullable in Table and in Oracle View NULL, NOT NULL]]="No","NOT NULL","NULL")=VLOOKUP(A35,[2]Model!C$2:I$228,6,FALSE) -> #REF! | T35: =VLOOKUP(B35,[2]Table!A$2:F$415,1,FALSE)=[3]!Table14[[#This Row],[Physical Name of Attribute (Name of column in Table) Supplied by DA Team]] -> #REF! | U35: =VLOOKUP(B35,Table!A$2:F$319,2,FALSE)=Table14[[#This Row],[Data type in Oracle VARCHAR2(n), DATE, NUMBER(m,n), TIMETSTAMP(6)]] -> FALSE | V35: =VLOOKUP(B35,Table!A$2:F$231,3,FALSE)=Table14[[#This Row],[Nullable in Table and in Oracle View NULL, NOT NULL]] -> TRUE | W35: =VLOOKUP(B35,Table!A$2:H$228,6,FALSE)=Table14[[#This Row],[Business Definition (To go into comments and into Meta Data Hub)]] -> TRUE | X35: =VLOOKUP((UPPER(SUBSTITUTE(A35," ","_"))),'[2]Consumer View'!A$2:I$329,1,FALSE) -> MONEY_MOVEMENT_ALTERNATE_ID | Y35: CCAL_REPL_OWNER | Z35: TXN | AA35: ORIG_SRC_STM_CODE | AD35: ccal_repl_owner.txn t where t.src_stm_id= '60' and t.ORIG_SRC_STM_CODE like 'MM%' and t.SRC_CRT_USRNM = 'BPMWRAPB'; | AH35: N
A36: Arrangement Originating Source System Code | B36: AR_ORIG_SRC_STM_CD | C36: Arrangement_Originating_Source_System_Provider_Code | D36: VARCHAR2(20) | E36: Yes | F36: character varying(20) | G36: Yes | H36: Code that represents the source system from which CDS database receives/obtains the underlying Arrangement from. | I36: ZTNB.#B066 | J36: Add | K36: 3 | O36: =VLOOKUP(A36,[1]Model!C$2:J$559,2,FALSE)=B36 -> TRUE | P36: =VLOOKUP(A36,Model!C$2:G$228,5,FALSE)=D36 -> TRUE | Q36: =VLOOKUP(A36,[2]Model!C$2:L$228,8,FALSE) -> 185 | R36: =VLOOKUP(A36,[2]Model!C$2:G$228,3,FALSE)=[3]!Table14[[#This Row],[Business Definition (To go into comments and into Meta Data Hub)]] -> #REF! | S36: =IF([3]!Table14[[#This Row],[Nullable in Table and in Oracle View NULL, NOT NULL]]="No","NOT NULL","NULL")=VLOOKUP(A36,[2]Model!C$2:I$228,6,FALSE) -> #REF! | T36: =VLOOKUP(B36,[2]Table!A$2:F$415,1,FALSE)=[3]!Table14[[#This Row],[Physical Name of Attribute (Name of column in Table) Supplied by DA Team]] -> #REF! | U36: =VLOOKUP(B36,Table!A$2:F$319,2,FALSE)=Table14[[#This Row],[Data type in Oracle VARCHAR2(n), DATE, NUMBER(m,n), TIMETSTAMP(6)]] -> FALSE | V36: =VLOOKUP(B36,Table!A$2:F$231,3,FALSE)=Table14[[#This Row],[Nullable in Table and in Oracle View NULL, NOT NULL]] -> TRUE | W36: =VLOOKUP(B36,Table!A$2:H$228,6,FALSE)=Table14[[#This Row],[Business Definition (To go into comments and into Meta Data Hub)]] -> TRUE | X36: =VLOOKUP((UPPER(SUBSTITUTE(A36," ","_"))),'[2]Consumer View'!A$2:I$329,1,FALSE) -> ARRANGEMENT_ORIGINATING_SOURCE_SYSTEM_CODE | Y36: CCSI_OWNER | Z36: AR_DIM | AA36: ORIG_SRC_STM_CD | AD36: ccal_repl_owner.txn t join ccsi_owner.ar_dim ard ON ard.AR_ID = t.AR_ID and ard.eff_dt <= t.td and ard.end_dt > t.td | AE36: [9/6/24]: Reflected the change to use TXN.TD from Product Backlog Item 1912566: Change join condition and update data types for Activity. [9/17/24]: Changing to use TXN.AR_ID per Product Backlog Item 1998220: Fix Activity issues for Historical Load | AH36: Y
A37: Source System Id | B37: SRC_STM_ID | D37: NUMBER(38,0) | E37: Yes | F37: NUMERIC(38,0) | G37: Yes | H37: Source system Id coming from Transaction. This could be different from Source system Id coming from Arrangement information. | I37: 3 | J37: Add | K37: 3 | O37: =VLOOKUP(A37,[1]Model!C$2:J$559,2,FALSE)=B37 -> TRUE | P37: =VLOOKUP(A37,Model!C$2:G$228,5,FALSE)=D37 -> #N/A | Q37: =VLOOKUP(A37,[2]Model!C$2:L$228,8,FALSE) -> 163 | R37: =VLOOKUP(A37,[2]Model!C$2:G$228,3,FALSE)=[3]!Table14[[#This Row],[Business Definition (To go into comments and into Meta Data Hub)]] -> #REF! | S37: =IF([3]!Table14[[#This Row],[Nullable in Table and in Oracle View NULL, NOT NULL]]="No","NOT NULL","NULL")=VLOOKUP(A37,[2]Model!C$2:I$228,6,FALSE) -> #REF! | T37: =VLOOKUP(B37,[2]Table!A$2:F$415,1,FALSE)=[3]!Table14[[#This Row],[Physical Name of Attribute (Name of column in Table) Supplied by DA Team]] -> #REF! | U37: =VLOOKUP(B37,Table!A$2:F$319,2,FALSE)=Table14[[#This Row],[Data type in Oracle VARCHAR2(n), DATE, NUMBER(m,n), TIMETSTAMP(6)]] -> TRUE | V37: =VLOOKUP(B37,Table!A$2:F$231,3,FALSE)=Table14[[#This Row],[Nullable in Table and in Oracle View NULL, NOT NULL]] -> TRUE | W37: =VLOOKUP(B37,Table!A$2:H$228,6,FALSE)=Table14[[#This Row],[Business Definition (To go into comments and into Meta Data Hub)]] -> TRUE | X37: =VLOOKUP((UPPER(SUBSTITUTE(A37," ","_"))),'[2]Consumer View'!A$2:I$329,1,FALSE) -> SOURCE_SYSTEM_ID | Y37: CCAL_REPL_OWNER | Z37: TXN | AA37: SRC_STM_ID | AH37: N
A38: Source System Name | B38: SRC_STM_NM | C38: Source_System | D38: VARCHAR2(60) | E38: Yes | F38: character varying(60) | G38: Yes | H38: Name of the source system information coming from Transaction. e.g., SIS - Securities Industry Software, Raymond James, Raymond James Bank, Shadow Suite | I38: Broadridge Financial Solution IMPACT Back Office System | J38: Add | K38: 3 | O38: =VLOOKUP(A38,[1]Model!C$2:J$559,2,FALSE)=B38 -> TRUE | P38: =VLOOKUP(A38,Model!C$2:G$228,5,FALSE)=D38 -> #N/A | Q38: =VLOOKUP(A38,[2]Model!C$2:L$228,8,FALSE) -> 165 | R38: =VLOOKUP(A38,[2]Model!C$2:G$228,3,FALSE)=[3]!Table14[[#This Row],[Business Definition (To go into comments and into Meta Data Hub)]] -> #REF! | S38: =IF([3]!Table14[[#This Row],[Nullable in Table and in Oracle View NULL, NOT NULL]]="No","NOT NULL","NULL")=VLOOKUP(A38,[2]Model!C$2:I$228,6,FALSE) -> #REF! | T38: =VLOOKUP(B38,[2]Table!A$2:F$415,1,FALSE)=[3]!Table14[[#This Row],[Physical Name of Attribute (Name of column in Table) Supplied by DA Team]] -> #REF! | U38: =VLOOKUP(B38,Table!A$2:F$319,2,FALSE)=Table14[[#This Row],[Data type in Oracle VARCHAR2(n), DATE, NUMBER(m,n), TIMETSTAMP(6)]] -> FALSE | V38: =VLOOKUP(B38,Table!A$2:F$231,3,FALSE)=Table14[[#This Row],[Nullable in Table and in Oracle View NULL, NOT NULL]] -> TRUE | W38: =VLOOKUP(B38,Table!A$2:H$228,6,FALSE)=Table14[[#This Row],[Business Definition (To go into comments and into Meta Data Hub)]] -> TRUE | X38: =VLOOKUP((UPPER(SUBSTITUTE(A38," ","_"))),'[2]Consumer View'!A$2:I$329,1,FALSE) -> SOURCE_SYSTEM_NAME | Y38: COMMON_OWNER | Z38: SRC_STM_DIM | AA38: SRC_STM_NM | AD38: ccal_repl_owner.txn t left JOIN common_owner.src_stm_dim ss on t.src_stm_id = ss.src_stm_id | AH38: N
A39: Source Cancel / Revision Code | B39: SRC_CNCL_X_RVSN_CD | C39: Source_Cancel_or_Revision_Code | D39: VARCHAR2(3) | E39: Yes | F39: character varying(3) | G39: Yes | H39: Cancel or Revise Code in the source system | I39: CAN - Transaction has been canceled before verification or approval. CXL - Transaction has been revised or canceled after verification. CXR - Transaction is a rebill of a previous transaction and that the rebill has been revised or canceled. OFF - Transaction is an offset of a transaction that has been revised or canceled. OFR - Transaction is an offset of a rebill that has been revised or canceled. RBL - Transaction is a rebill of a transaction that has been revised. RTN - Indicates a piece of collateral has been returned during the term of a deal. IMP - Transaction is an offset of a rebill that has a factor adjustment | J39: Add | K39: 3 | O39: =VLOOKUP(A39,[1]Model!C$2:J$559,2,FALSE)=B39 -> TRUE | P39: =VLOOKUP(A39,Model!C$2:G$228,5,FALSE)=D39 -> #N/A | Q39: =VLOOKUP(A39,[2]Model!C$2:L$228,8,FALSE) -> 166 | R39: =VLOOKUP(A39,[2]Model!C$2:G$228,3,FALSE)=[3]!Table14[[#This Row],[Business Definition (To go into comments and into Meta Data Hub)]] -> #REF! | S39: =IF([3]!Table14[[#This Row],[Nullable in Table and in Oracle View NULL, NOT NULL]]="No","NOT NULL","NULL")=VLOOKUP(A39,[2]Model!C$2:I$228,6,FALSE) -> #REF! | T39: =VLOOKUP(B39,[2]Table!A$2:F$415,1,FALSE)=[3]!Table14[[#This Row],[Physical Name of Attribute (Name of column in Table) Supplied by DA Team]] -> #REF! | U39: =VLOOKUP(B39,Table!A$2:F$319,2,FALSE)=Table14[[#This Row],[Data type in Oracle VARCHAR2(n), DATE, NUMBER(m,n), TIMETSTAMP(6)]] -> FALSE | V39: =VLOOKUP(B39,Table!A$2:F$231,3,FALSE)=Table14[[#This Row],[Nullable in Table and in Oracle View NULL, NOT NULL]] -> TRUE | W39: =VLOOKUP(B39,Table!A$2:H$228,6,FALSE)=Table14[[#This Row],[Business Definition (To go into comments and into Meta Data Hub)]] -> TRUE | X39: =VLOOKUP((UPPER(SUBSTITUTE(A39," ","_"))),'[2]Consumer View'!A$2:I$329,1,FALSE) -> #N/A | Y39: CCAL_REPL_OWNER | Z39: TXN | AA39: SRC_CXL_REV | AE39: [6/3/24]: Modified data type for Redshift from 255 to 3 | AH39: N
A40: Source Option Class Code | B40: SRC_OPT_CLSS_CD | C40: Source_Option_Class_Code | D40: VARCHAR2(50) | E40: Yes | F40: character varying(50) | G40: Yes | H40: The code that determines what type of transaction the record contains. For SIS activity the values depend on the record type. | I40: M W C B I H L F P Y R A G J 2 X D T | J40: Add | K40: 3 | O40: =VLOOKUP(A40,[1]Model!C$2:J$559,2,FALSE)=B40 -> TRUE | P40: =VLOOKUP(A40,Model!C$2:G$228,5,FALSE)=D40 -> #N/A | Q40: =VLOOKUP(A40,[2]Model!C$2:L$228,8,FALSE) -> 167 | R40: =VLOOKUP(A40,[2]Model!C$2:G$228,3,FALSE)=[3]!Table14[[#This Row],[Business Definition (To go into comments and into Meta Data Hub)]] -> #REF! | S40: =IF([3]!Table14[[#This Row],[Nullable in Table and in Oracle View NULL, NOT NULL]]="No","NOT NULL","NULL")=VLOOKUP(A40,[2]Model!C$2:I$228,6,FALSE) -> #REF! | T40: =VLOOKUP(B40,[2]Table!A$2:F$415,1,FALSE)=[3]!Table14[[#This Row],[Physical Name of Attribute (Name of column in Table) Supplied by DA Team]] -> #REF! | U40: =VLOOKUP(B40,Table!A$2:F$319,2,FALSE)=Table14[[#This Row],[Data type in Oracle VARCHAR2(n), DATE, NUMBER(m,n), TIMETSTAMP(6)]] -> FALSE | V40: =VLOOKUP(B40,Table!A$2:F$231,3,FALSE)=Table14[[#This Row],[Nullable in Table and in Oracle View NULL, NOT NULL]] -> TRUE | W40: =VLOOKUP(B40,Table!A$2:H$228,6,FALSE)=Table14[[#This Row],[Business Definition (To go into comments and into Meta Data Hub)]] -> TRUE | X40: =VLOOKUP((UPPER(SUBSTITUTE(A40," ","_"))),'[2]Consumer View'!A$2:I$329,1,FALSE) -> SOURCE_OPTION_CLASS_CODE | Y40: CCAL_REPL_OWNER | Z40: TXN | AA40: SRC_OPT_CLS | AH40: N
...

Sheet Table-View
A1: 1. View Name - | B1: ACTIVITY_FACT_V | I1: Please read review comments on Table Functional Description, Data Type and Business Definition
A2: 2. Table Name - | B2: AVY_FACT
A3: 3. View Schema Name - | B3: SSDS_DAL_OWNER
A4: 4. Table Schema Name - | B4: TRANSACTIONS_OWNER
A5: 5. Table Functional Description - | B5: This table consists of trades and transactions (Cash and Securities) to meet investment objective of a client. | I5: BA Responsbility | J5: BA Responsbility | K5: BA Responsbility | L5: DA Responsibility
A6: 6. Filter Criteria - | B6: Transaction Trade Date >= DATE '2017-10-01'. Refer to [ETL Notes] tab for more filters
A7: 7. Grain (Logical primary key) - | B7: Refer to [ETL Notes] tab
A8: 8. Semantic View Schema Name - | B8: ENTERPRISE_SEMANTIC_OWNER
A9: 9. Semantic View Name - | B9: Activity_Fact_cross_domain_V
A10: Note:
A11: Lighthouse Target | Y11: Source | AD11: Transformation
A12: Logical Name of Attribute (Name of column in View without underscores) | B12: Physical Name of Attribute (Name of column in Table) Supplied by DA Team | C12: Semantic Column Name | D12: Data type in Oracle VARCHAR2(n), DATE, NUMBER(m,n), TIMETSTAMP(6) | E12: Nullable in Table and in Oracle View NULL, NOT NULL | F12: Data type in Redshift | G12: Nullable in RedshiftTable | H12: Business Definition (To go into comments and into Meta Data Hub) | I12: Sample data values | J12: Action on Attribute Add,Update,Remove, Blank | K12: Action Version | L12: Table PBI Number | M12: List Functional PBI | N12: Include in View. Populated with N only when not to be shown in the view. | O12: Is on Data Model DA responsibility | P12: Model Data Type match TRUE/FALSE DA Responsibilty | Q12: Column2 | R12: Model Defs. Match | S12: Model Nullable Match | T12: On Table | U12: table data type | V12: table Nullable | W12: table defintions | X12: On View | Y12: Source Schema | Z12: Source Table | AA12: Source Attribute Name | AB12: Data Type | AC12: Nullable? | AD12: Transformation /Business Rules /Join Conditions | AE12: Notes / Comments | AF12: Indicator | AG12: Domain | AH12: Cross-Domain
A13: SHADOW Transaction Type Code | B13: SHDW_TXN_TP_CD | C13: Shadow_Transaction_Type_Code | D13: VARCHAR2(50) | E13: Yes | F13: character varying(50) | G13: Yes | H13: Possible values: ORG, OLD, NEW, REV, REP. | I13: OLD ORG REP REV NEW | J13: Add | K13: 3 | O13: =VLOOKUP(A13,[1]Model!C$2:J$559,2,FALSE)=B13 -> TRUE | P13: =VLOOKUP(A13,Model!C$2:G$228,5,FALSE)=D13 -> #N/A | Q13: =VLOOKUP(A13,[2]Model!C$2:L$228,8,FALSE) -> 179 | R13: =VLOOKUP(A13,[2]Model!C$2:G$228,3,FALSE)=[3]!Table14[[#This Row],[Business Definition (To go into comments and into Meta Data Hub)]] -> #REF! | S13: =IF([3]!Table14[[#This Row],[Nullable in Table and in Oracle View NULL, NOT NULL]]="No","NOT NULL","NULL")=VLOOKUP(A13,[2]Model!C$2:I$228,6,FALSE) -> #REF! | T13: =VLOOKUP(B13,[2]Table!A$2:F$415,1,FALSE)=[3]!Table14[[#This Row],[Physical Name of Attribute (Name of column in Table) Supplied by DA Team]] -> #REF! | U13: =VLOOKUP(B13,Table!A$2:F$319,2,FALSE)=Table1[[#This Row],[Data type in Oracle VARCHAR2(n), DATE, NUMBER(m,n), TIMETSTAMP(6)]] -> FALSE | V13: =VLOOKUP(B13,Table!A$2:F$231,3,FALSE)=Table1[[#This Row],[Nullable in Table and in Oracle View NULL, NOT NULL]] -> TRUE | W13: =VLOOKUP(B13,Table!A$2:H$228,6,FALSE)=Table1[[#This Row],[Business Definition (To go into comments and into Meta Data Hub)]] -> TRUE | X13: =VLOOKUP((UPPER(SUBSTITUTE(A13," ","_"))),'[2]Consumer View'!A$2:I$329,1,FALSE) -> SHADOW_TRANSACTION_TYPE_CODE | Y13: CCAL_REPL_OWNER | Z13: TXN | AA13: SRC_TXN_TP | AH13: N
A14: SHADOW Transaction Type Name | B14: SHDW_TXN_TP_NM | C14: Shadow_Transaction_Type | D14: VARCHAR2(50) | E14: Yes | F14: character varying(50) | G14: Yes | H14: Name of the Shadow Transaction Type Code. | J14: Add | K14: 3 | O14: =VLOOKUP(A14,[1]Model!C$2:J$559,2,FALSE)=B14 -> TRUE | P14: =VLOOKUP(A14,Model!C$2:G$228,5,FALSE)=D14 -> #N/A | Q14: =VLOOKUP(A14,[2]Model!C$2:L$228,8,FALSE) -> 177 | R14: =VLOOKUP(A14,[2]Model!C$2:G$228,3,FALSE)=[3]!Table14[[#This Row],[Business Definition (To go into comments and into Meta Data Hub)]] -> #REF! | S14: =IF([3]!Table14[[#This Row],[Nullable in Table and in Oracle View NULL, NOT NULL]]="No","NOT NULL","NULL")=VLOOKUP(A14,[2]Model!C$2:I$228,6,FALSE) -> #REF! | T14: =VLOOKUP(B14,[2]Table!A$2:F$415,1,FALSE)=[3]!Table14[[#This Row],[Physical Name of Attribute (Name of column in Table) Supplied by DA Team]] -> #REF! | U14: =VLOOKUP(B14,Table!A$2:F$319,2,FALSE)=Table1[[#This Row],[Data type in Oracle VARCHAR2(n), DATE, NUMBER(m,n), TIMETSTAMP(6)]] -> FALSE | V14: =VLOOKUP(B14,Table!A$2:F$231,3,FALSE)=Table1[[#This Row],[Nullable in Table and in Oracle View NULL, NOT NULL]] -> TRUE | W14: =VLOOKUP(B14,Table!A$2:H$228,6,FALSE)=Table1[[#This Row],[Business Definition (To go into comments and into Meta Data Hub)]] -> TRUE | X14: =VLOOKUP((UPPER(SUBSTITUTE(A14," ","_"))),'[2]Consumer View'!A$2:I$329,1,FALSE) -> SHADOW_TRANSACTION_TYPE_NAME | Y14: CCAL_REPL_OWNER | Z14: SHDW_TXN_TP | AA14: SRC_TXN_TP_NM | AD14: Look up using TXN.SRC_TXN_TP=SHDW_TXN_TP.SRC_TXN_TP | AH14: N
A15: IMPACT Source Action Code | B15: IMP_SRC_ACTN_CD | C15: IMPACT_Source_Action_Code | D15: VARCHAR2(1) | E15: Yes | F15: character varying(1) | G15: Yes | H15: Code representing Action Type in IMPACT source system | I15: M C I F A P N R Y S K Q U V T | J15: Add | K15: 3 | O15: =VLOOKUP(A15,[1]Model!C$2:J$559,2,FALSE)=B15 -> TRUE | P15: =VLOOKUP(A15,Model!C$2:G$228,5,FALSE)=D15 -> TRUE | Q15: =VLOOKUP(A15,[2]Model!C$2:L$228,8,FALSE) -> 181 | R15: =VLOOKUP(A15,[2]Model!C$2:G$228,3,FALSE)=[3]!Table14[[#This Row],[Business Definition (To go into comments and into Meta Data Hub)]] -> #REF! | S15: =IF([3]!Table14[[#This Row],[Nullable in Table and in Oracle View NULL, NOT NULL]]="No","NOT NULL","NULL")=VLOOKUP(A15,[2]Model!C$2:I$228,6,FALSE) -> #REF! | T15: =VLOOKUP(B15,[2]Table!A$2:F$415,1,FALSE)=[3]!Table14[[#This Row],[Physical Name of Attribute (Name of column in Table) Supplied by DA Team]] -> #REF! | U15: =VLOOKUP(B15,Table!A$2:F$319,2,FALSE)=Table1[[#This Row],[Data type in Oracle VARCHAR2(n), DATE, NUMBER(m,n), TIMETSTAMP(6)]] -> FALSE | V15: =VLOOKUP(B15,Table!A$2:F$231,3,FALSE)=Table1[[#This Row],[Nullable in Table and in Oracle View NULL, NOT NULL]] -> TRUE | W15: =VLOOKUP(B15,Table!A$2:H$228,6,FALSE)=Table1[[#This Row],[Business Definition (To go into comments and into Meta Data Hub)]] -> TRUE | X15: =VLOOKUP((UPPER(SUBSTITUTE(A15," ","_"))),'[2]Consumer View'!A$2:I$329,1,FALSE) -> IMPACT_SOURCE_ACTION_CODE | Y15: CCAL_REPL_OWNER | Z15: TXN | AA15: SRC_ACTN_CODE | AH15: N
A16: IMPACT Source Action Name | B16: IMP_SRC_ACTN_NM | C16: IMPACT_Source_Action | D16: VARCHAR2(100) | E16: Yes | F16: character varying(100) | G16: Yes | H16: Name representing Action Type in IMPACT source system | I16: 1 Security offering document is changed A Amend B Blind Broker Fail C Cancel D Trade Settled F Pool Factor Change I Insert K Failed Trade L Trade Canceled (was matched) M Trade Matched (was unmatched) N Trade Settled O Failed obligation in Net P Trade Settled Q Trade Revision R Rate Revision S Trade Settled T Failed Trade U Trade Un-Netted V DK W Trade Revision X Trade Unmatched (was matched) Y Trade Settled | J16: Add | K16: 3 | O16: =VLOOKUP(A16,[1]Model!C$2:J$559,2,FALSE)=B16 -> TRUE | P16: =VLOOKUP(A16,Model!C$2:G$228,5,FALSE)=D16 -> TRUE | Q16: =VLOOKUP(A16,[2]Model!C$2:L$228,8,FALSE) -> 183 | R16: =VLOOKUP(A16,[2]Model!C$2:G$228,3,FALSE)=[3]!Table14[[#This Row],[Business Definition (To go into comments and into Meta Data Hub)]] -> #REF! | S16: =IF([3]!Table14[[#This Row],[Nullable in Table and in Oracle View NULL, NOT NULL]]="No","NOT NULL","NULL")=VLOOKUP(A16,[2]Model!C$2:I$228,6,FALSE) -> #REF! | T16: =VLOOKUP(B16,[2]Table!A$2:F$415,1,FALSE)=[3]!Table14[[#This Row],[Physical Name of Attribute (Name of column in Table) Supplied by DA Team]] -> #REF! | U16: =VLOOKUP(B16,Table!A$2:F$319,2,FALSE)=Table1[[#This Row],[Data type in Oracle VARCHAR2(n), DATE, NUMBER(m,n), TIMETSTAMP(6)]] -> FALSE | V16: =VLOOKUP(B16,Table!A$2:F$231,3,FALSE)=Table1[[#This Row],[Nullable in Table and in Oracle View NULL, NOT NULL]] -> TRUE | W16: =VLOOKUP(B16,Table!A$2:H$228,6,FALSE)=Table1[[#This Row],[Business Definition (To go into comments and into Meta Data Hub)]] -> TRUE | X16: =VLOOKUP((UPPER(SUBSTITUTE(A16," ","_"))),'[2]Consumer View'!A$2:I$329,1,FALSE) -> IMPACT_SOURCE_ACTION_NAME | Y16: REFERENCE_REPL_OWNER | Z16: IMPCT_ACTION_LKU | AA16: desc_text | AD16: ccal_repl_owner.txn t left join ccal_repl_owner.impct_action_lku lk ON t.src_actn_code = impct_action_lku.action_code | AE16: Note to Dev team: IMPCT_ACTION_LKU table exists only in CDS DB but not available in SSDS/Lighthouse DB. [6/3/24]: Modified target data type for Oracle and Redshift. PBI 1912566 | AH16: N
